Workbook

Sheet Start
B2: TxDOT HIGHWAY CONSTRUCTION BID PROGRAM
B3: Unit-price proposal worksheet · Dallas District example · 2024 Standard Specifications
B5: This workbook prices a TxDOT highway proposal the way a contractor builds a bid: direct unit cost, job overhead, bond, insurance, profit, Item 500 mobilization, and the electronic bid guaranty. It does not submit a bid. Official proposals go through iCX (Integrated Contractor Exchange) after prequalification. Yellow cells with blue type are inputs. Green type is a cross-sheet formula. Replace the sample project before use.
B7: HOW TO USE THIS WORKBOOK
B8: Step | C8: Sheet | D8: What you do
B9: 1 | C9: Project | D9: Enter contractor, CSJ, highway, letting, engineer's estimate, working days, bidding capacity, and DBE goal.
B10: 2 | C10: Markups | D10: Set field overhead, duration, bond rate, insurance, home-office, and profit. The sheet solves a loaded bid that recovers those costs.
B11: 3 | C11: Unit Cost | D11: Build direct cost for production items from crew-day production, labor, equipment, material, waste, and subcontract.
B12: 4 | C12: Bid Proposal | D12: Confirm quantities from the proposal bid insert. Override any unit price. Blank override uses the loaded price.
B13: 5 | C13: Mobilization | D13: Price Item 500. Payment is staged under the 2024 spec and is capped relative to the contract on early estimates.
B14: 6 | C14: Bond & Checks | D14: Confirm the 2% bid guaranty, capacity, major items, zero prices, and mobilization share before iCX lock.
B16: RULES THIS MODEL FOLLOWS
B17: Bid form | C17: Unit price on every bid item. Total bid is the sum of quantity × unit price. A blank unit price is a non-responsive risk.
B18: Bid guaranty | C18: Required when the engineer's estimate exceeds $25,000. Amount is 2% of the estimate, rounded to the nearest $1,000, not to exceed $100,000. Electronic bids require an electronic bid bond (Surety2000 or Surepath).
B19: iCX | C19: Prequalified contractors bid in iCX. Paper bonds and checks are not bid guaranties on electronic bids. Bids must be in the vault by the letting time. Addenda must be acknowledged.
B20: Capacity | C20: Bidding capacity is set from the confidential questionnaire: net working capital × TxDOT factor. A bid over remaining capacity can be rejected.
B21: Major item | C21: An item whose extended amount is at least 5% of the original contract or $100,000, whichever is less. Major items stay major.
B22: Item 500 | C22: 2024 Mobilization is paid in stages (bond/insurance invoice, plant setup cap, then 1% / 5% / 10% earned). Early payments are the lesser of a percent of the lump sum and a percent of the contract. A very high mobilization bid draws review and slows cash.
B23: Unbalance | C23: TxDOT reviews materially unbalanced bids (front-loaded or token prices on items likely to overrun). This sheet flags $0 prices, penny prices, and unit prices outside the benchmark band.
B24: DBE / federal | C24: Federal-aid jobs carry a DBE goal. Commitment forms are part of the proposal, not a line on the bid schedule.
B26: DISCLAIMER · Not an official TxDOT form and not a substitute for the proposal, plans, general notes, or special provisions. Benchmark prices are planning figures drawn from published 2025–26 letting summaries (median low-bidder prices on common items) and typical Texas unit-price ranges. They are not TxDOT's official average low bid prices. Pull current district tabs from the TxDOT Bid Tabulations dashboard and data.texas.gov before you lock a number. Spec payment language is summarized from the 2024 Item 500; confirm the special provision actually in the proposal (SP 500-001 applies on large jobs).
B28: Import | C28: Paste the Whitley & Siddons EasyLinkPro export on WS Import. Proposal, estimate, and bond read that sheet.

Sheet WS Import
B2: WHITLEY & SIDDONS IMPORT
B3: EasyLinkPro export · paste the job header, then paste bid items under row 15
B5: In EasyLinkPro, open the job and export the bid-item list to Excel. Paste the control (CSJ), highway, county, district, letting date, and engineer's estimate into the yellow header. Paste item rows starting at row 16, under these columns. Accepted W&S names: Bid Item, Item, Item Number, Bid Code, Item Code; Description or Bid Item Description; Unit or UOM; Quantity, Qty, or Bid Qty. Codes can be 500-7001, 500 7001, or 5007001. Clear old rows before a new job. Direct cost and unit-price overrides stay on BidProposal.
B7: JOB HEADER | E7: FROM THE W&S JOB LINE
B8: CSJ / control | C8: 0047-14-128 | E8: Engineer's estimate | F8: 2850000 | G8: W&S column: Estimate
B9: Highway | C9: US 75 | E9: Description | F9: Mill, overlay, safety, and drainage
B10: Limits | C10: SH 121 to FM 455 | E10: Working days | F10: 140 | G10: From the proposal if W&S index does not carry it
B11: County | C11: Collin | E11: Items pasted | F11: =COUNTA(B16:B215) -> 33
B12: District | C12: Dallas | E12: Status | F12: =IF(F11=0,"Paste items under the headers","Proposal is reading this sheet") -> Proposal is reading this sheet
B13: Letting date | C13: 2026-11-04
B14: Bid Item / Item Number / Bid Code | C14: Description / Bid Item Description | D14: Unit / UOM | E14: Quantity / Qty / Bid Qty | F14: Optional | G14: Engineer unit, reference only | H14: Normalized
B15: Bid code | C15: Description | D15: Unit | E15: Quantity | F15: Category | G15: Eng. unit | H15: Code used
B16: 500-7001 | C16: Mobilization | D16: LS | E16: 1 | F16: Mobilization | H16: =IF(B16="","",IF(ISNUMBER(SEARCH("-",B16&"")),UPPER(TRIM(B16)),IF(LEN(SUBSTITUTE(SUBSTITUTE(UPPER(TRIM(B16&""))," ",""),"-",""))=8,LEFT(SUBSTITUTE(SUBSTITUTE(UPPER(TRIM(B16&""))," ",""),"-",""),4)&"-"&RIGHT(SUBSTITUTE(SUBSTITUTE(UPPER(TRIM(B16&""))," ",""),"-",""),4),IF(LEN(SUBSTITUTE(SUBSTITUTE(UPPER(TRIM(B16&""))," ",""),"-",""))=7,LEFT(SUBSTITUTE(SUBSTITUTE(UPPER(TRIM(B16&""))," ",""),"-",""),3)&"-"&RIGHT(SUBSTITUTE(SUBSTITUTE(UPPER(TRIM(B16&""))," ",""),"-",""),4),UPPER(TRIM(B16)))))) -> 500-7001
B17: 502-7001 | C17: Barricades, signs and traffic handling | D17: MO | E17: 7 | F17: Traffic control | H17: =IF(B17="","",IF(ISNUMBER(SEARCH("-",B17&"")),UPPER(TRIM(B17)),IF(LEN(SUBSTITUTE(SUBSTITUTE(UPPER(TRIM(B17&""))," ",""),"-",""))=8,LEFT(SUBSTITUTE(SUBSTITUTE(UPPER(TRIM(B17&""))," ",""),"-",""),4)&"-"&RIGHT(SUBSTITUTE(SUBSTITUTE(UPPER(TRIM(B17&""))," ",""),"-",""),4),IF(LEN(SUBSTITUTE(SUBSTITUTE(UPPER(TRIM(B17&""))," ",""),"-",""))=7,LEFT(SUBSTITUTE(SUBSTITUTE(UPPER(TRIM(B17&""))," ",""),"-",""),3)&"-"&RIGHT(SUBSTITUTE(SUBSTITUTE(UPPER(TRIM(B17&""))," ",""),"-",""),4),UPPER(TRIM(B17)))))) -> 502-7001
B18: 503-7001 | C18: Portable changeable message sign | D18: DAY | E18: 140 | F18: Traffic control | H18: =IF(B18="","",IF(ISNUMBER(SEARCH("-",B18&"")),UPPER(TRIM(B18)),IF(LEN(SUBSTITUTE(SUBSTITUTE(UPPER(TRIM(B18&""))," ",""),"-",""))=8,LEFT(SUBSTITUTE(SUBSTITUTE(UPPER(TRIM(B18&""))," ",""),"-",""),4)&"-"&RIGHT(SUBSTITUTE(SUBSTITUTE(UPPER(TRIM(B18&""))," ",""),"-",""),4),IF(LEN(SUBSTITUTE(SUBSTITUTE(UPPER(TRIM(B18&""))," ",""),"-",""))=7,LEFT(SUBSTITUTE(SUBSTITUTE(UPPER(TRIM(B18&""))," ",""),"-",""),3)&"-"&RIGHT(SUBSTITUTE(SUBSTITUTE(UPPER(TRIM(B18&""))," ",""),"-",""),4),UPPER(TRIM(B18)))))) -> 503-7001
B19: 505-7001 | C19: TMA (stationary) | D19: DAY | E19: 140 | F19: Traffic control | H19: =IF(B19="","",IF(ISNUMBER(SEARCH("-",B19&"")),UPPER(TRIM(B19)),IF(LEN(SUBSTITUTE(SUBSTITUTE(UPPER(TRIM(B19&""))," ",""),"-",""))=8,LEFT(SUBSTITUTE(SUBSTITUTE(UPPER(TRIM(B19&""))," ",""),"-",""),4)&"-"&RIGHT(SUBSTITUTE(SUBSTITUTE(UPPER(TRIM(B19&""))," ",""),"-",""),4),IF(LEN(SUBSTITUTE(SUBSTITUTE(UPPER(TRIM(B19&""))," ",""),"-",""))=7,LEFT(SUBSTITUTE(SUBSTITUTE(UPPER(TRIM(B19&""))," ",""),"-",""),3)&"-"&RIGHT(SUBSTITUTE(SUBSTITUTE(UPPER(TRIM(B19&""))," ",""),"-",""),4),UPPER(TRIM(B19)))))) -> 505-7001
B20: 505-7003 | C20: TMA (mobile operation) | D20: DAY | E20: 30 | F20: Traffic control | H20: =IF(B20="","",IF(ISNUMBER(SEARCH("-",B20&"")),UPPER(TRIM(B20)),IF(LEN(SUBSTITUTE(SUBSTITUTE(UPPER(TRIM(B20&""))," ",""),"-",""))=8,LEFT(SUBSTITUTE(SUBSTITUTE(UPPER(TRIM(B20&""))," ",""),"-",""),4)&"-"&RIGHT(SUBSTITUTE(SUBSTITUTE(UPPER(TRIM(B20&""))," ",""),"-",""),4),IF(LEN(SUBSTITUTE(SUBSTITUTE(UPPER(TRIM(B20&""))," ",""),"-",""))=7,LEFT(SUBSTITUTE(SUBSTITUTE(UPPER(TRIM(B20&""))," ",""),"-",""),3)&"-"&RIGHT(SUBSTITUTE(SUBSTITUTE(UPPER(TRIM(B20&""))," ",""),"-",""),4),UPPER(TRIM(B20)))))) -> 505-7003
B21: 506-7039 | C21: Temp sedmt cont fence (install) | D21: LF | E21: 4200 | F21: SW3P | H21: =IF(B21="","",IF(ISNUMBER(SEARCH("-",B21&"")),UPPER(TRIM(B21)),IF(LEN(SUBSTITUTE(SUBSTITUTE(UPPER(TRIM(B21&""))," ",""),"-",""))=8,LEFT(SUBSTITUTE(SUBSTITUTE(UPPER(TRIM(B21&""))," ",""),"-",""),4)&"-"&RIGHT(SUBSTITUTE(SUBSTITUTE(UPPER(TRIM(B21&""))," ",""),"-",""),4),IF(LEN(SUBSTITUTE(SUBSTITUTE(UPPER(TRIM(B21&""))," ",""),"-",""))=7,LEFT(SUBSTITUTE(SUBSTITUTE(UPPER(TRIM(B21&""))," ",""),"-",""),3)&"-"&RIGHT(SUBSTITUTE(SUBSTITUTE(UPPER(TRIM(B21&""))," ",""),"-",""),4),UPPER(TRIM(B21)))))) -> 506-7039
B22: 506-7041 | C22: Temp sedmt cont fence (remove) | D22: LF | E22: 4200 | F22: SW3P | H22: =IF(B22="","",IF(ISNUMBER(SEARCH("-",B22&"")),UPPER(TRIM(B22)),IF(LEN(SUBSTITUTE(SUBSTITUTE(UPPER(TRIM(B22&""))," ",""),"-",""))=8,LEFT(SUBSTITUTE(SUBSTITUTE(UPPER(TRIM(B22&""))," ",""),"-",""),4)&"-"&RIGHT(SUBSTITUTE(SUBSTITUTE(UPPER(TRIM(B22&""))," ",""),"-",""),4),IF(LEN(SUBSTITUTE(SUBSTITUTE(UPPER(TRIM(B22&""))," ",""),"-",""))=7,LEFT(SUBSTITUTE(SUBSTITUTE(UPPER(TRIM(B22&""))," ",""),"-",""),3)&"-"&RIGHT(SUBSTITUTE(SUBSTITUTE(UPPER(TRIM(B22&""))," ",""),"-",""),4),UPPER(TRIM(B22)))))) -> 506-7041
B23: 100-7002 | C23: Preparing right of way | D23: STA | E23: 18 | F23: Earthwork | H23: =IF(B23="","",IF(ISNUMBER(SEARCH("-",B23&"")),UPPER(TRIM(B23)),IF(LEN(SUBSTITUTE(SUBSTITUTE(UPPER(TRIM(B23&""))," ",""),"-",""))=8,LEFT(SUBSTITUTE(SUBSTITUTE(UPPER(TRIM(B23&""))," ",""),"-",""),4)&"-"&RIGHT(SUBSTITUTE(SUBSTITUTE(UPPER(TRIM(B23&""))," ",""),"-",""),4),IF(LEN(SUBSTITUTE(SUBSTITUTE(UPPER(TRIM(B23&""))," ",""),"-",""))=7,LEFT(SUBSTITUTE(SUBSTITUTE(UPPER(TRIM(B23&""))," ",""),"-",""),3)&"-"&RIGHT(SUBSTITUTE(SUBSTITUTE(UPPER(TRIM(B23&""))," ",""),"-",""),4),UPPER(TRIM(B23)))))) -> 100-7002
B24: 104-7006 | C24: Removing conc (pav) | D24: SY | E24: 2800 | F24: Earthwork | H24: =IF(B24="","",IF(ISNUMBER(SEARCH("-",B24&"")),UPPER(TRIM(B24)),IF(LEN(SUBSTITUTE(SUBSTITUTE(UPPER(TRIM(B24&""))," ",""),"-",""))=8,LEFT(SUBSTITUTE(SUBSTITUTE(UPPER(TRIM(B24&""))," ",""),"-",""),4)&"-"&RIGHT(SUBSTITUTE(SUBSTITUTE(UPPER(TRIM(B24&""))," ",""),"-",""),4),IF(LEN(SUBSTITUTE(SUBSTITUTE(UPPER(TRIM(B24&""))," ",""),"-",""))=7,LEFT(SUBSTITUTE(SUBSTITUTE(UPPER(TRIM(B24&""))," ",""),"-",""),3)&"-"&RIGHT(SUBSTITUTE(SUBSTITUTE(UPPER(TRIM(B24&""))," ",""),"-",""),4),UPPER(TRIM(B24)))))) -> 104-7006
B25: 110-7001 | C25: Excavation (roadway) | D25: CY | E25: 8600 | F25: Earthwork | H25: =IF(B25="","",IF(ISNUMBER(SEARCH("-",B25&"")),UPPER(TRIM(B25)),IF(LEN(SUBSTITUTE(SUBSTITUTE(UPPER(TRIM(B25&""))," ",""),"-",""))=8,LEFT(SUBSTITUTE(SUBSTITUTE(UPPER(TRIM(B25&""))," ",""),"-",""),4)&"-"&RIGHT(SUBSTITUTE(SUBSTITUTE(UPPER(TRIM(B25&""))," ",""),"-",""),4),IF(LEN(SUBSTITUTE(SUBSTITUTE(UPPER(TRIM(B25&""))," ",""),"-",""))=7,LEFT(SUBSTITUTE(SUBSTITUTE(UPPER(TRIM(B25&""))," ",""),"-",""),3)&"-"&RIGHT(SUBSTITUTE(SUBSTITUTE(UPPER(TRIM(B25&""))," ",""),"-",""),4),UPPER(TRIM(B25)))))) -> 110-7001
B26: 132-7005 | C26: Embankment (final)(ord comp)(ty C) | D26: CY | E26: 4100 | F26: Earthwork | H26: =IF(B26="","",IF(ISNUMBER(SEARCH("-",B26&"")),UPPER(TRIM(B26)),IF(LEN(SUBSTITUTE(SUBSTITUTE(UPPER(TRIM(B26&""))," ",""),"-",""))=8,LEFT(SUBSTITUTE(SUBSTITUTE(UPPER(TRIM(B26&""))," ",""),"-",""),4)&"-"&RIGHT(SUBSTITUTE(SUBSTITUTE(UPPER(TRIM(B26&""))," ",""),"-",""),4),IF(LEN(SUBSTITUTE(SUBSTITUTE(UPPER(TRIM(B26&""))," ",""),"-",""))=7,LEFT(SUBSTITUTE(SUBSTITUTE(UPPER(TRIM(B26&""))," ",""),"-",""),3)&"-"&RIGHT(SUBSTITUTE(SUBSTITUTE(UPPER(TRIM(B26&""))," ",""),"-",""),4),UPPER(TRIM(B26)))))) -> 132-7005
B27: 164-7002 | C27: Broadcast seed (perm)(rural)(clay) | D27: SY | E27: 18000 | F27: Roadside | H27: =IF(B27="","",IF(ISNUMBER(SEARCH("-",B27&"")),UPPER(TRIM(B27)),IF(LEN(SUBSTITUTE(SUBSTITUTE(UPPER(TRIM(B27&""))," ",""),"-",""))=8,LEFT(SUBSTITUTE(SUBSTITUTE(UPPER(TRIM(B27&""))," ",""),"-",""),4)&"-"&RIGHT(SUBSTITUTE(SUBSTITUTE(UPPER(TRIM(B27&""))," ",""),"-",""),4),IF(LEN(SUBSTITUTE(SUBSTITUTE(UPPER(TRIM(B27&""))," ",""),"-",""))=7,LEFT(SUBSTITUTE(SUBSTITUTE(UPPER(TRIM(B27&""))," ",""),"-",""),3)&"-"&RIGHT(SUBSTITUTE(SUBSTITUTE(UPPER(TRIM(B27&""))," ",""),"-",""),4),UPPER(TRIM(B27)))))) -> 164-7002
... B48: 512-7001 | C48: Port CTB (furn & inst)(safety shaped) | D48: LF | E48: 400 | F48: Traffic control | H48: =IF(B48="","",IF(ISNUMBER(SEARCH("-",B48&"")),UPPER(TRIM(B48)),IF(LEN(SUBSTITUTE(SUBSTITUTE(UPPER(TRIM(B48&""))," ",""),"-",""))=8,LEFT(SUBSTITUTE(SUBSTITUTE(UPPER(TRIM(B48&""))," ",""),"-",""),4)&"-"&RIGHT(SUBSTITUTE(SUBSTITUTE(UPPER(TRIM(B48&""))," ",""),"-",""),4),IF(LEN(SUBSTITUTE(SUBSTITUTE(UPPER(TRIM(B48&""))," ",""),"-",""))=7,LEFT(SUBSTITUTE(SUBSTITUTE(UPPER(TRIM(B48&""))," ",""),"-",""),3)&"-"&RIGHT(SUBSTITUTE(SUBSTITUTE(UPPER(TRIM(B48&""))," ",""),"-",""),4),UPPER(TRIM(B48)))))) -> 512-7001
H49: =IF(B49="","",IF(ISNUMBER(SEARCH("-",B49&"")),UPPER(TRIM(B49)),IF(LEN(SUBSTITUTE(SUBSTITUTE(UPPER(TRIM(B49&""))," ",""),"-",""))=8,LEFT(SUBSTITUTE(SUBSTITUTE(UPPER(TRIM(B49&""))," ",""),"-",""),4)&"-"&RIGHT(SUBSTITUTE(SUBSTITUTE(UPPER(TRIM(B49&""))," ",""),"-",""),4),IF(LEN(SUBSTITUTE(SUBSTITUTE(UPPER(TRIM(B49&""))," ",""),"-",""))=7,LEFT(SUBSTITUTE(SUBSTITUTE(UPPER(TRIM(B49&""))," ",""),"-",""),3)&"-"&RIGHT(SUBSTITUTE(SUBSTITUTE(UPPER(TRIM(B49&""))," ",""),"-",""),4),UPPER(TRIM(B49))))))
H50: =IF(B50="","",IF(ISNUMBER(SEARCH("-",B50&"")),UPPER(TRIM(B50)),IF(LEN(SUBSTITUTE(SUBSTITUTE(UPPER(TRIM(B50&""))," ",""),"-",""))=8,LEFT(SUBSTITUTE(SUBSTITUTE(UPPER(TRIM(B50&""))," ",""),"-",""),4)&"-"&RIGHT(SUBSTITUTE(SUBSTITUTE(UPPER(TRIM(B50&""))," ",""),"-",""),4),IF(LEN(SUBSTITUTE(SUBSTITUTE(UPPER(TRIM(B50&""))," ",""),"-",""))=7,LEFT(SUBSTITUTE(SUBSTITUTE(UPPER(TRIM(B50&""))," ",""),"-",""),3)&"-"&RIGHT(SUBSTITUTE(SUBSTITUTE(UPPER(TRIM(B50&""))," ",""),"-",""),4),UPPER(TRIM(B50))))))
H51: =IF(B51="","",IF(ISNUMBER(SEARCH("-",B51&"")),UPPER(TRIM(B51)),IF(LEN(SUBSTITUTE(SUBSTITUTE(UPPER(TRIM(B51&""))," ",""),"-",""))=8,LEFT(SUBSTITUTE(SUBSTITUTE(UPPER(TRIM(B51&""))," ",""),"-",""),4)&"-"&RIGHT(SUBSTITUTE(SUBSTITUTE(UPPER(TRIM(B51&""))," ",""),"-",""),4),IF(LEN(SUBSTITUTE(SUBSTITUTE(UPPER(TRIM(B51&""))," ",""),"-",""))=7,LEFT(SUBSTITUTE(SUBSTITUTE(UPPER(TRIM(B51&""))," ",""),"-",""),3)&"-"&RIGHT(SUBSTITUTE(SUBSTITUTE(UPPER(TRIM(B51&""))," ",""),"-",""),4),UPPER(TRIM(B51))))))
H52: =IF(B52="","",IF(ISNUMBER(SEARCH("-",B52&"")),UPPER(TRIM(B52)),IF(LEN(SUBSTITUTE(SUBSTITUTE(UPPER(TRIM(B52&""))," ",""),"-",""))=8,LEFT(SUBSTITUTE(SUBSTITUTE(UPPER(TRIM(B52&""))," ",""),"-",""),4)&"-"&RIGHT(SUBSTITUTE(SUBSTITUTE(UPPER(TRIM(B52&""))," ",""),"-",""),4),IF(LEN(SUBSTITUTE(SUBSTITUTE(UPPER(TRIM(B52&""))," ",""),"-",""))=7,LEFT(SUBSTITUTE(SUBSTITUTE(UPPER(TRIM(B52&""))," ",""),"-",""),3)&"-"&RIGHT(SUBSTITUTE(SUBSTITUTE(UPPER(TRIM(B52&""))," ",""),"-",""),4),UPPER(TRIM(B52))))))
H53: =IF(B53="","",IF(ISNUMBER(SEARCH("-",B53&"")),UPPER(TRIM(B53)),IF(LEN(SUBSTITUTE(SUBSTITUTE(UPPER(TRIM(B53&""))," ",""),"-",""))=8,LEFT(SUBSTITUTE(SUBSTITUTE(UPPER(TRIM(B53&""))," ",""),"-",""),4)&"-"&RIGHT(SUBSTITUTE(SUBSTITUTE(UPPER(TRIM(B53&""))," ",""),"-",""),4),IF(LEN(SUBSTITUTE(SUBSTITUTE(UPPER(TRIM(B53&""))," ",""),"-",""))=7,LEFT(SUBSTITUTE(SUBSTITUTE(UPPER(TRIM(B53&""))," ",""),"-",""),3)&"-"&RIGHT(SUBSTITUTE(SUBSTITUTE(UPPER(TRIM(B53&""))," ",""),"-",""),4),UPPER(TRIM(B53))))))
H54: =IF(B54="","",IF(ISNUMBER(SEARCH("-",B54&"")),UPPER(TRIM(B54)),IF(LEN(SUBSTITUTE(SUBSTITUTE(UPPER(TRIM(B54&""))," ",""),"-",""))=8,LEFT(SUBSTITUTE(SUBSTITUTE(UPPER(TRIM(B54&""))," ",""),"-",""),4)&"-"&RIGHT(SUBSTITUTE(SUBSTITUTE(UPPER(TRIM(B54&""))," ",""),"-",""),4),IF(LEN(SUBSTITUTE(SUBSTITUTE(UPPER(TRIM(B54&""))," ",""),"-",""))=7,LEFT(SUBSTITUTE(SUBSTITUTE(UPPER(TRIM(B54&""))," ",""),"-",""),3)&"-"&RIGHT(SUBSTITUTE(SUBSTITUTE(UPPER(TRIM(B54&""))," ",""),"-",""),4),UPPER(TRIM(B54))))))
H55: =IF(B55="","",IF(ISNUMBER(SEARCH("-",B55&"")),UPPER(TRIM(B55)),IF(LEN(SUBSTITUTE(SUBSTITUTE(UPPER(TRIM(B55&""))," ",""),"-",""))=8,LEFT(SUBSTITUTE(SUBSTITUTE(UPPER(TRIM(B55&""))," ",""),"-",""),4)&"-"&RIGHT(SUBSTITUTE(SUBSTITUTE(UPPER(TRIM(B55&""))," ",""),"-",""),4),IF(LEN(SUBSTITUTE(SUBSTITUTE(UPPER(TRIM(B55&""))," ",""),"-",""))=7,LEFT(SUBSTITUTE(SUBSTITUTE(UPPER(TRIM(B55&""))," ",""),"-",""),3)&"-"&RIGHT(SUBSTITUTE(SUBSTITUTE(UPPER(TRIM(B55&""))," ",""),"-",""),4),UPPER(TRIM(B55))))))
H56: =IF(B56="","",IF(ISNUMBER(SEARCH("-",B56&"")),UPPER(TRIM(B56)),IF(LEN(SUBSTITUTE(SUBSTITUTE(UPPER(TRIM(B56&""))," ",""),"-",""))=8,LEFT(SUBSTITUTE(SUBSTITUTE(UPPER(TRIM(B56&""))," ",""),"-",""),4)&"-"&RIGHT(SUBSTITUTE(SUBSTITUTE(UPPER(TRIM(B56&""))," ",""),"-",""),4),IF(LEN(SUBSTITUTE(SUBSTITUTE(UPPER(TRIM(B56&""))," ",""),"-",""))=7,LEFT(SUBSTITUTE(SUBSTITUTE(UPPER(TRIM(B56&""))," ",""),"-",""),3)&"-"&RIGHT(SUBSTITUTE(SUBSTITUTE(UPPER(TRIM(B56&""))," ",""),"-",""),4),UPPER(TRIM(B56))))))
H57: =IF(B57="","",IF(ISNUMBER(SEARCH("-",B57&"")),UPPER(TRIM(B57)),IF(LEN(SUBSTITUTE(SUBSTITUTE(UPPER(TRIM(B57&""))," ",""),"-",""))=8,LEFT(SUBSTITUTE(SUBSTITUTE(UPPER(TRIM(B57&""))," ",""),"-",""),4)&"-"&RIGHT(SUBSTITUTE(SUBSTITUTE(UPPER(TRIM(B57&""))," ",""),"-",""),4),IF(LEN(SUBSTITUTE(SUBSTITUTE(UPPER(TRIM(B57&""))," ",""),"-",""))=7,LEFT(SUBSTITUTE(SUBSTITUTE(UPPER(TRIM(B57&""))," ",""),"-",""),3)&"-"&RIGHT(SUBSTITUTE(SUBSTITUTE(UPPER(TRIM(B57&""))," ",""),"-",""),4),UPPER(TRIM(B57))))))
H58: =IF(B58="","",IF(ISNUMBER(SEARCH("-",B58&"")),UPPER(TRIM(B58)),IF(LEN(SUBSTITUTE(SUBSTITUTE(UPPER(TRIM(B58&""))," ",""),"-",""))=8,LEFT(SUBSTITUTE(SUBSTITUTE(UPPER(TRIM(B58&""))," ",""),"-",""),4)&"-"&RIGHT(SUBSTITUTE(SUBSTITUTE(UPPER(TRIM(B58&""))," ",""),"-",""),4),IF(LEN(SUBSTITUTE(SUBSTITUTE(UPPER(TRIM(B58&""))," ",""),"-",""))=7,LEFT(SUBSTITUTE(SUBSTITUTE(UPPER(TRIM(B58&""))," ",""),"-",""),3)&"-"&RIGHT(SUBSTITUTE(SUBSTITUTE(UPPER(TRIM(B58&""))," ",""),"-",""),4),UPPER(TRIM(B58))))))
H59: =IF(B59="","",IF(ISNUMBER(SEARCH("-",B59&"")),UPPER(TRIM(B59)),IF(LEN(SUBSTITUTE(SUBSTITUTE(UPPER(TRIM(B59&""))," ",""),"-",""))=8,LEFT(SUBSTITUTE(SUBSTITUTE(UPPER(TRIM(B59&""))," ",""),"-",""),4)&"-"&RIGHT(SUBSTITUTE(SUBSTITUTE(UPPER(TRIM(B59&""))," ",""),"-",""),4),IF(LEN(SUBSTITUTE(SUBSTITUTE(UPPER(TRIM(B59&""))," ",""),"-",""))=7,LEFT(SUBSTITUTE(SUBSTITUTE(UPPER(TRIM(B59&""))," ",""),"-",""),3)&"-"&RIGHT(SUBSTITUTE(SUBSTITUTE(UPPER(TRIM(B59&""))," ",""),"-",""),4),UPPER(TRIM(B59))))))
H60: =IF(B60="","",IF(ISNUMBER(SEARCH("-",B60&"")),UPPER(TRIM(B60)),IF(LEN(SUBSTITUTE(SUBSTITUTE(UPPER(TRIM(B60&""))," ",""),"-",""))=8,LEFT(SUBSTITUTE(SUBSTITUTE(UPPER(TRIM(B60&""))," ",""),"-",""),4)&"-"&RIGHT(SUBSTITUTE(SUBSTITUTE(UPPER(TRIM(B60&""))," ",""),"-",""),4),IF(LEN(SUBSTITUTE(SUBSTITUTE(UPPER(TRIM(B60&""))," ",""),"-",""))=7,LEFT(SUBSTITUTE(SUBSTITUTE(UPPER(TRIM(B60&""))," ",""),"-",""),3)&"-"&RIGHT(SUBSTITUTE(SUBSTITUTE(UPPER(TRIM(B60&""))," ",""),"-",""),4),UPPER(TRIM(B60))))))
... H215: =IF(B215="","",IF(ISNUMBER(SEARCH("-",B215&"")),UPPER(TRIM(B215)),IF(LEN(SUBSTITUTE(SUBSTITUTE(UPPER(TRIM(B215&""))," ",""),"-",""))=8,LEFT(SUBSTITUTE(SUBSTITUTE(UPPER(TRIM(B215&""))," ",""),"-",""),4)&"-"&RIGHT(SUBSTITUTE(SUBSTITUTE(UPPER(TRIM(B215&""))," ",""),"-",""),4),IF(LEN(SUBSTITUTE(SUBSTITUTE(UPPER(TRIM(B215&""))," ",""),"-",""))=7,LEFT(SUBSTITUTE(SUBSTITUTE(UPPER(TRIM(B215&""))," ",""),"-",""),3)&"-"&RIGHT(SUBSTITUTE(SUBSTITUTE(UPPER(TRIM(B215&""))," ",""),"-",""),4),UPPER(TRIM(B215))))))

Sheet Summary
B2: BID SUMMARY
B3: =CONCATENATE(Project!F7," · ",Project!F8," · ",Project!F10," District · ",Project!C6) -> US 75 · SH 121 to FM 455 · Dallas District · North Texas Paving, LLC
B5: BID BY CATEGORY
B6: Category | C6: Bid amount | D6: Share | E6: Direct cost
B7: Mobilization | C7: =SUMIF(BidProposal!$D$6:$D$155,B7,BidProposal!$N$6:$N$155) -> 134053.49 | D7: =IF(BidProposal!$N$156=0,0,C7/BidProposal!$N$156) -> 0.052132701 | E7: =SUMIF(BidProposal!$D$6:$D$155,B7,BidProposal!$I$6:$I$155) -> 0
B8: Traffic control | C8: =SUMIF(BidProposal!$D$6:$D$155,B8,BidProposal!$N$6:$N$155) -> 117701.36 | D8: =IF(BidProposal!$N$156=0,0,C8/BidProposal!$N$156) -> 0.045773445 | E8: =SUMIF(BidProposal!$D$6:$D$155,B8,BidProposal!$I$6:$I$155) -> 83100
B9: SW3P | C9: =SUMIF(BidProposal!$D$6:$D$155,B9,BidProposal!$N$6:$N$155) -> 18076.437 | D9: =IF(BidProposal!$N$156=0,0,C9/BidProposal!$N$156) -> 0.0070298317 | E9: =SUMIF(BidProposal!$D$6:$D$155,B9,BidProposal!$I$6:$I$155) -> 12762.4
B10: Earthwork | C10: =SUMIF(BidProposal!$D$6:$D$155,B10,BidProposal!$N$6:$N$155) -> 239185.73 | D10: =IF(BidProposal!$N$156=0,0,C10/BidProposal!$N$156) -> 0.093018079 | E10: =SUMIF(BidProposal!$D$6:$D$155,B10,BidProposal!$I$6:$I$155) -> 168870.89
B11: Base | C11: =SUMIF(BidProposal!$D$6:$D$155,B11,BidProposal!$N$6:$N$155) -> 176511.44 | D11: =IF(BidProposal!$N$156=0,0,C11/BidProposal!$N$156) -> 0.068644377 | E11: =SUMIF(BidProposal!$D$6:$D$155,B11,BidProposal!$I$6:$I$155) -> 124621.33
B12: Paving | C12: =SUMIF(BidProposal!$D$6:$D$155,B12,BidProposal!$N$6:$N$155) -> 1336351.3 | D12: =IF(BidProposal!$N$156=0,0,C12/BidProposal!$N$156) -> 0.51970005 | E12: =SUMIF(BidProposal!$D$6:$D$155,B12,BidProposal!$I$6:$I$155) -> 943496.25
B13: Drainage | C13: =SUMIF(BidProposal!$D$6:$D$155,B13,BidProposal!$N$6:$N$155) -> 178646.59 | D13: =IF(BidProposal!$N$156=0,0,C13/BidProposal!$N$156) -> 0.069474726 | E13: =SUMIF(BidProposal!$D$6:$D$155,B13,BidProposal!$I$6:$I$155) -> 126128.8
B14: Roadside | C14: =SUMIF(BidProposal!$D$6:$D$155,B14,BidProposal!$N$6:$N$155) -> 215648.94 | D14: =IF(BidProposal!$N$156=0,0,C14/BidProposal!$N$156) -> 0.083864745 | E14: =SUMIF(BidProposal!$D$6:$D$155,B14,BidProposal!$I$6:$I$155) -> 152253.35
B15: Safety | C15: =SUMIF(BidProposal!$D$6:$D$155,B15,BidProposal!$N$6:$N$155) -> 61986.553 | D15: =IF(BidProposal!$N$156=0,0,C15/BidProposal!$N$156) -> 0.024106246 | E15: =SUMIF(BidProposal!$D$6:$D$155,B15,BidProposal!$I$6:$I$155) -> 43764
B16: Signing | C16: =SUMIF(BidProposal!$D$6:$D$155,B16,BidProposal!$N$6:$N$155) -> 17690.614 | D16: =IF(BidProposal!$N$156=0,0,C16/BidProposal!$N$156) -> 0.0068797874 | E16: =SUMIF(BidProposal!$D$6:$D$155,B16,BidProposal!$I$6:$I$155) -> 12490
B17: Markings | C17: =SUMIF(BidProposal!$D$6:$D$155,B17,BidProposal!$N$6:$N$155) -> 75537.176 | D17: =IF(BidProposal!$N$156=0,0,C17/BidProposal!$N$156) -> 0.029376013 | E17: =SUMIF(BidProposal!$D$6:$D$155,B17,BidProposal!$I$6:$I$155) -> 53331.067
B18: Total | C18: =SUM(C7:C17) -> 2571389.7 | D18: =SUM(D7:D17) -> 1 | E18: =SUM(E7:E17) -> 1720818.1
B20: OUTCOME
B21: Total bid | C21: =BidProposal!N156 -> 2571389.7
B22: Engineer's estimate | C22: =EE -> 2850000
B23: Variance to estimate | C23: =C21-C22 -> -278610.32
B24: Variance percent | C24: =IF(C22=0,0,C21/C22-1) -> -0.097758006
B25: Bid guaranty | C25: ='Bond & Checks'!C11 -> 57000
B26: Capacity headroom | C26: ='Bond & Checks'!C17 -> 9028610.3

Sheet Project
B2: PROJECT SETUP
B3: Sample job is a Collin County mill-and-overlay with safety and drainage. Replace every yellow cell with the proposal in hand.
B5: CONTRACTOR | E5: PROJECT
B6: Legal name | C6: North Texas Paving, LLC | E6: CSJ | F6: ='WS Import'!C8 -> 0047-14-128 | G6: From WS Import. Paste the Whitley & Siddons job line there.
B7: TxDOT vendor ID | C7: VT00000000 | E7: Highway | F7: ='WS Import'!C9 -> US 75
B8: Estimator | C8: Estimator | E8: Limits | F8: ='WS Import'!C10 -> SH 121 to FM 455
B9: Date prepared | C9: 2026-10-02 | E9: County | F9: ='WS Import'!C11 -> Collin
E10: District | F10: ='WS Import'!C12 -> Dallas
E11: Letting date | F11: ='WS Import'!C13 -> 2026-11-04
E12: Spec book | F12: 2024
B14: MONEY AND TIME | E14: BID POLICY INPUTS
B15: Engineer's estimate | C15: ='WS Import'!F8 -> 2850000 | E15: Funding | F15: Federal-aid
B16: Working days | C16: ='WS Import'!F10 -> 140 | E16: DBE goal | F16: 0.08
B17: Months on site | C17: 7 | E17: Mobilization target share | F17: 0.055 | G17: Share of work items, before Item 500. Cash and review flag, not a spec cap on the bid.
B18: Bidding capacity | C18: 18000000 | E18: Contingency on direct | F18: 0.02 | G18: Unallocated field risk. Sits in the load, not as a bid item.
B19: Capacity already committed | C19: 6400000 | E19: Proposal addenda received | F19: 0 | G19: Count of addenda acknowledged in iCX. Must match the letting.
B20: Remaining capacity | C20: =C18-C19 -> 11600000
B22: LIVE SNAPSHOT · updates from the Bid Proposal
B23: Work-item direct cost | C23: =Markups!C11 -> 0.035 | E23: Capacity headroom is remaining prequalification capacity minus this bid. A negative number means this proposal, stacked on work already committed, exceeds the bidding capacity on the confidential questionnaire. TxDOT can reject a bid that exceeds available capacity. Capacity is net working capital times the factor in the approval letter — enter the letter amount, not a guess from revenue.
B24: Loaded work-item bid | C24: =Markups!C18 -> 2091234.5
B25: Item 500 mobilization bid | C25: =Mobilization!C12 -> 134053.49
B26: Total bid | C26: =BidProposal!N156 -> 2571389.7
B27: Bid vs engineer's estimate | C27: =IF(C15=0,"-",BidProposal!N156/C15-1) -> -0.097758006
B28: Bid guaranty required | C28: ='Bond & Checks'!C11 -> 57000
B29: Capacity headroom after this bid | C29: =C20-BidProposal!N156 -> 9028610.3

Sheet Markups
B2: INDIRECTS, BOND, INSURANCE, PROFIT
B3: Rates load the work items. Item 500 is priced on the Mobilization sheet so bond cash is not double-counted.
B5: JOB OVERHEAD AND RATES
B6: Field overhead per month | C6: 48000 | D6: Superintendent, pickup, field office, small tools, sanitation.
B7: Months on site | C7: =MonthsOnSite -> 7 | D7: From Project.
B8: Field overhead total | C8: =C6*C7 -> 336000 | D8: Fixed cost spread across work items.
B9: Bond rate on contract amount | C9: 0.009 | D9: Payment and performance bond. Often 0.6% to 1.5%.
B10: Insurance rate on contract amount | C10: 0.018 | D10: GL, builder's risk, umbrella. Workers' comp belongs in the labor rate.
B11: Home-office rate on contract amount | C11: 0.035 | D11: G&A share assigned to this job.
B12: Profit on contract amount | C12: 0.08 | D12: Target margin on the loaded work-item total, before Item 500.
B13: Contingency on direct | C13: =Contingency -> 0.02 | D13: From Project. Applied to direct cost, then loaded.
B15: LOAD SOLVE · work items only, Item 500 excluded
B16: Direct cost of work items | C16: =SUMIF(BidProposal!B6:B155,"<>500-7001",BidProposal!I6:I155) -> 1720818.1 | D16: Sum of quantity × direct unit cost, excluding Item 500.
B17: Contingency dollars | C17: =C16*C13 -> 34416.362 | D17: Contingency rate times direct.
B18: Direct + contingency + field overhead | C18: =C16+C17+C8 -> 2091234.5 | D18: Numerator of the load.
B19: Rate load (bond + insurance + G&A + profit) | C19: =C9+C10+C11+C12 -> 0.142 | D19: These rates apply to the loaded work-item bid.
B20: Loaded work-item bid | C20: =IF((1-C19)<=0,"Rate load must be under 100%",(C18)/(1-C19)) -> 2437336.2 | D20: C = (direct + contingency + field OH) / (1 − bond − insurance − G&A − profit).
B21: Markup factor on direct | C21: =IF(C16=0,1,C20/C16) -> 1.4163822 | D21: Suggested unit price = direct unit × this factor, unless overridden.
B22: Dollars of load | C22: =C20-C16 -> 716518.1 | D22: Overhead, contingency, bond, insurance, G&A, and profit.
B24: Why the division: bond, insurance, home office, and profit are percents of the bid, not of direct cost. Adding them on top of direct understates the bid. The solve grosses them up so the rates land on the contract amount. If you override unit prices on the proposal, the Bid Proposal sheet shows whether the overrides still recover this load.
B28: WHERE THE LOAD GOES
B29: Component | C29: Amount | D29: Share of loaded work bid
B30: Direct work | C30: =C16 -> 1720818.1 | D30: =IF($C$20=0,0,C30/$C$20) -> 0.7060241
B31: Contingency | C31: =C17 -> 34416.362 | D31: =IF($C$20=0,0,C31/$C$20) -> 0.014120482
B32: Field overhead | C32: =C8 -> 336000 | D32: =IF($C$20=0,0,C32/$C$20) -> 0.13785542
B33: Bond | C33: =C9*C20 -> 21936.026 | D33: =IF($C$20=0,0,C33/$C$20) -> 0.009
B34: Insurance | C34: =C10*C20 -> 43872.051 | D34: =IF($C$20=0,0,C34/$C$20) -> 0.018
B35: Home office | C35: =C11*C20 -> 85306.767 | D35: =IF($C$20=0,0,C35/$C$20) -> 0.035
B36: Profit | C36: =C12*C20 -> 194986.9 | D36: =IF($C$20=0,0,C36/$C$20) -> 0.08
B37: Loaded work-item bid | C37: =C20 -> 2437336.2 | D37: =IF($C$20=0,0,C37/$C$20) -> 1

Sheet Unit Cost
B2: DIRECT UNIT COST BUILDUP
B3: Crew-day method. Direct unit = labor/day÷production + equipment/day÷production + material×(1+waste) + subcontract. Items left off this sheet use the manual direct cost on Bid Proposal.
B5: Bid code | C5: Description | D5: Unit | E5: Production / crew-day | F5: Labor $ / day | G5: Equipment $ / day | H5: Material $ / unit | I5: Waste | J5: Sub $ / unit | K5: Labor $ / unit | L5: Equip $ / unit | M5: Material loaded | N5: Direct $ / unit
B6: 110-7001 | C6: Excavation (roadway) | D6: CY | E6: 900 | F6: 2400 | G6: 3100 | H6: 0 | I6: 0.05 | J6: 0 | K6: =IF(E6=0,0,F6/E6) -> 2.6666667 | L6: =IF(E6=0,0,G6/E6) -> 3.4444444 | M6: =H6*(1+I6) -> 0 | N6: =K6+L6+M6+J6 -> 6.1111111
B7: 132-7005 | C7: Embankment (final)(ord comp)(ty C) | D7: CY | E7: 750 | F7: 2200 | G7: 2800 | H7: 6.5 | I7: 0.08 | J7: 0 | K7: =IF(E7=0,0,F7/E7) -> 2.9333333 | L7: =IF(E7=0,0,G7/E7) -> 3.7333333 | M7: =H7*(1+I7) -> 7.02 | N7: =K7+L7+M7+J7 -> 13.686667
B8: 164-7002 | C8: Broadcast seed (perm)(rural)(clay) | D8: SY | E8: 8000 | F8: 1400 | G8: 900 | H8: 0.18 | I8: 0.05 | J8: 0 | K8: =IF(E8=0,0,F8/E8) -> 0.175 | L8: =IF(E8=0,0,G8/E8) -> 0.1125 | M8: =H8*(1+I8) -> 0.189 | N8: =K8+L8+M8+J8 -> 0.4765
B9: 247-7194 | C9: Flex base (compl in place)(ty A gr 4) | D9: CY | E9: 450 | F9: 2600 | G9: 3400 | H9: 22 | I9: 0.06 | J9: 0 | K9: =IF(E9=0,0,F9/E9) -> 5.7777778 | L9: =IF(E9=0,0,G9/E9) -> 7.5555556 | M9: =H9*(1+I9) -> 23.32 | N9: =K9+L9+M9+J9 -> 36.653333
B10: 310-7004 | C10: Prime coat | D10: GAL | E10: 6000 | F10: 1800 | G10: 1600 | H10: 2.4 | I10: 0.03 | J10: 0 | K10: =IF(E10=0,0,F10/E10) -> 0.3 | L10: =IF(E10=0,0,G10/E10) -> 0.26666667 | M10: =H10*(1+I10) -> 2.472 | N10: =K10+L10+M10+J10 -> 3.0386667
B11: 354-7051 | C11: Plane asph conc pav (2 in) | D11: SY | E11: 9000 | F11: 2200 | G11: 4500 | H11: 0 | I11: 0 | J11: 0 | K11: =IF(E11=0,0,F11/E11) -> 0.24444444 | L11: =IF(E11=0,0,G11/E11) -> 0.5 | M11: =H11*(1+I11) -> 0 | N11: =K11+L11+M11+J11 -> 0.74444444
B12: 3076-7022 | C12: D-GR HMA ty D SAC-B PG70-22 | D12: TON | E12: 1400 | F12: 3200 | G12: 6800 | H12: 78 | I12: 0.04 | J12: 0 | K12: =IF(E12=0,0,F12/E12) -> 2.2857143 | L12: =IF(E12=0,0,G12/E12) -> 4.8571429 | M12: =H12*(1+I12) -> 81.12 | N12: =K12+L12+M12+J12 -> 88.262857
B13: 3076-7008 | C13: D-GR HMA ty B PG64-22 | D13: TON | E13: 1500 | F13: 3000 | G13: 6400 | H13: 68 | I13: 0.04 | J13: 0 | K13: =IF(E13=0,0,F13/E13) -> 2 | L13: =IF(E13=0,0,G13/E13) -> 4.2666667 | M13: =H13*(1+I13) -> 70.72 | N13: =K13+L13+M13+J13 -> 76.986667
B14: 464-7005 | C14: RC pipe (cl III)(24 in) | D14: LF | E14: 160 | F14: 2400 | G14: 1800 | H14: 68 | I14: 0.03 | J14: 0 | K14: =IF(E14=0,0,F14/E14) -> 15 | L14: =IF(E14=0,0,G14/E14) -> 11.25 | M14: =H14*(1+I14) -> 70.04 | N14: =K14+L14+M14+J14 -> 96.29
B15: 529-7009 | C15: Curb and gutter (ty II) | D15: LF | E15: 350 | F15: 2100 | G15: 900 | H15: 14.5 | I15: 0.05 | J15: 0 | K15: =IF(E15=0,0,F15/E15) -> 6 | L15: =IF(E15=0,0,G15/E15) -> 2.5714286 | M15: =H15*(1+I15) -> 15.225 | N15: =K15+L15+M15+J15 -> 23.796429
B16: 531-7001 | C16: Conc sidewalks (4 in) | D16: SY | E16: 180 | F16: 1800 | G16: 700 | H16: 38 | I16: 0.05 | J16: 0 | K16: =IF(E16=0,0,F16/E16) -> 10 | L16: =IF(E16=0,0,G16/E16) -> 3.8888889 | M16: =H16*(1+I16) -> 39.9 | N16: =K16+L16+M16+J16 -> 53.788889
B17: 540-7001 | C17: MTL W-beam GD fen (tim post) | D17: LF | E17: 250 | F17: 1600 | G17: 800 | H17: 18 | I17: 0.02 | J17: 0 | K17: =IF(E17=0,0,F17/E17) -> 6.4 | L17: =IF(E17=0,0,G17/E17) -> 3.2 | M17: =H17*(1+I17) -> 18.36 | N17: =K17+L17+M17+J17 -> 27.96
... B21: 502-7001 | C21: Barricades, signs and traffic handling | D21: MO | E21: 1 | F21: 2800 | G21: 900 | H21: 600 | I21: 0 | J21: 0 | K21: =IF(E21=0,0,F21/E21) -> 2800 | L21: =IF(E21=0,0,G21/E21) -> 900 | M21: =H21*(1+I21) -> 600 | N21: =K21+L21+M21+J21 -> 4300
B23: Labor $/day is the loaded crew (wages, payroll tax, workers' comp), not bare wage. Equipment $/day is internal rate or rented blue-book, including fuel and the operator only if the operator is not already in the labor crew. Material is delivered price. Waste covers yield loss, not sales tax if tax is already in the material price. These starter rates are Dallas-area planning figures for a 2026 letting — replace them with your quotes. HMAC material near $68–$78/ton is binder plus aggregate before haul and placement; if your quote is a furnished-and-placed subcontract, put that price in Sub and zero out labor, equipment, and material.

Sheet BidProposal
A2: BID PROPOSAL · UNIT PRICE SCHEDULE
A3: =CONCATENATE("CSJ ",Project!F6," ",Project!F7," ",Project!F8," ",Project!F9," County ",Project!F10," District Letting ",TEXT(Project!F11,"YYYY-MM-DD")," ",Project!C6) -> CSJ 0047-14-128 US 75 SH 121 to FM 455 Collin County Dallas District Letting 2026-11-04 North Texas Paving, LLC
A4: Yellow cells are inputs. Bid unit price uses the override if one is entered; otherwise direct unit × markup factor. Benchmarks are planning bands, not the engineer's prices. A flag is a review item, not a rejection.
A5: Seq | B5: Bid code | C5: Description | D5: Category | E5: Unit | F5: Quantity | G5: Manual direct | H5: Buildup direct | I5: Direct amount | J5: Factor | K5: Suggested unit | L5: Override unit | M5: Bid unit price | N5: Bid amount | O5: % of bid | P5: Bench low | Q5: Bench typical | R5: Bench high | S5: Flag
A6: =IF('WS Import'!H16="","",ROW()-5) -> 1 | B6: =IF('WS Import'!H16="","",'WS Import'!H16) -> 500-7001 | C6: =IF('WS Import'!H16="","",'WS Import'!C16) -> Mobilization | D6: =IF(B6="","",IF('WS Import'!F16<>"",'WS Import'!F16,IF(LEFT(B6,3)="500","Mobilization",IF(OR(LEFT(B6,3)="502",LEFT(B6,3)="503",LEFT(B6,3)="505",LEFT(B6,3)="512"),"Traffic control",IF(LEFT(B6,3)="506","SW3P",IF(OR(LEFT(B6,3)="100",LEFT(B6,3)="104",LEFT(B6,3)="105",LEFT(B6,3)="110",LEFT(B6,3)="132"),"Earthwork",IF(LEFT(B6,3)="247","Base",IF(OR(LEFT(B6,3)="310",LEFT(B6,3)="316",LEFT(B6,3)="340",LEFT(B6,3)="341",LEFT(B6,3)="344",LEFT(B6,3)="354",LEFT(B6,4)="3076",LEFT(B6,4)="3077",LEFT(B6,4)="3080"),"Paving",IF(OR(LEFT(B6,3)="400",LEFT(B6,3)="416",LEFT(B6,3)="420",LEFT(B6,3)="422",LEFT(B6,3)="432",LEFT(B6,3)="450",LEFT(B6,3)="462",LEFT(B6,3)="464",LEFT(B6,3)="465",LEFT(B6,3)="466",LEFT(B6,3)="467",LEFT(B6,3)="496"),"Drainage",IF(OR(LEFT(B6,3)="164",LEFT(B6,3)="168",LEFT(B6,3)="169",LEFT(B6,3)="529",LEFT(B6,3)="530",LEFT(B6,3)="531"),"Roadside",IF(OR(LEFT(B6,3)="540",LEFT(B6,3)="542",LEFT(B6,3)="544",LEFT(B6,3)="545"),"Safety",IF(OR(LEFT(B6,3)="644",LEFT(B6,3)="636",LEFT(B6,3)="658"),"Signing",IF(OR(LEFT(B6,3)="666",LEFT(B6,3)="668",LEFT(B6,3)="672",LEFT(B6,3)="677",LEFT(B6,3)="678"),"Markings","Other"))))))))))))) -> Mobilization | E6: =IF(B6="","",'WS Import'!D16) -> LS | F6: =IF(B6="","",'WS Import'!E16) -> 1 | G6: 0 | H6: =IF(B6="","",IFERROR(INDEX('Unit Cost'!$N$6:$N$21,MATCH(B6,'Unit Cost'!$B$6:$B$21,0)),0)) -> 0 | I6: =IF(B6="","",F6*IF(H6>0,H6,G6)) -> 0 | J6: =IF(B6="","",IF(B6="500-7001",1,MarkupFactor)) -> 1 | K6: =IF(B6="","",IF(B6="500-7001",Mobilization!C11,IF(F6=0,0,IF(H6>0,H6,G6)*J6))) -> 134053.49 | M6: =IF(B6="","",IF(L6="",K6,L6)) -> 134053.49 | N6: =IF(B6="","",F6*M6) -> 134053.49 | O6: =IF(OR(B6="",$N$156=""),"",N6/$N$156) -> 0.052132701 | P6: 80000 | Q6: 250000 | R6: 450000 | S6: =IF(OR(B6="",F6=""),"",IF(M6=0,"ZERO PRICE",IF(AND(M6>0,M6<=0.05,Q6>1),"TOKEN PRICE",IF(AND(Q6>0,M6<P6*0.5),"UNDER BAND",IF(AND(R6>0,M6>R6*1.5),"OVER BAND",IF(AND(B6="500-7001",$N$156>0,N6/$N$156>0.1),"MOB > 10%","OK")))))) -> OK
A7: =IF('WS Import'!H17="","",ROW()-5) -> 2 | B7: =IF('WS Import'!H17="","",'WS Import'!H17) -> 502-7001 | C7: =IF('WS Import'!H17="","",'WS Import'!C17) -> Barricades, signs and traffic handling | D7: =IF(B7="","",IF('WS Import'!F17<>"",'WS Import'!F17,IF(LEFT(B7,3)="500","Mobilization",IF(OR(LEFT(B7,3)="502",LEFT(B7,3)="503",LEFT(B7,3)="505",LEFT(B7,3)="512"),"Traffic control",IF(LEFT(B7,3)="506","SW3P",IF(OR(LEFT(B7,3)="100",LEFT(B7,3)="104",LEFT(B7,3)="105",LEFT(B7,3)="110",LEFT(B7,3)="132"),"Earthwork",IF(LEFT(B7,3)="247","Base",IF(OR(LEFT(B7,3)="310",LEFT(B7,3)="316",LEFT(B7,3)="340",LEFT(B7,3)="341",LEFT(B7,3)="344",LEFT(B7,3)="354",LEFT(B7,4)="3076",LEFT(B7,4)="3077",LEFT(B7,4)="3080"),"Paving",IF(OR(LEFT(B7,3)="400",LEFT(B7,3)="416",LEFT(B7,3)="420",LEFT(B7,3)="422",LEFT(B7,3)="432",LEFT(B7,3)="450",LEFT(B7,3)="462",LEFT(B7,3)="464",LEFT(B7,3)="465",LEFT(B7,3)="466",LEFT(B7,3)="467",LEFT(B7,3)="496"),"Drainage",IF(OR(LEFT(B7,3)="164",LEFT(B7,3)="168",LEFT(B7,3)="169",LEFT(B7,3)="529",LEFT(B7,3)="530",LEFT(B7,3)="531"),"Roadside",IF(OR(LEFT(B7,3)="540",LEFT(B7,3)="542",LEFT(B7,3)="544",LEFT(B7,3)="545"),"Safety",IF(OR(LEFT(B7,3)="644",LEFT(B7,3)="636",LEFT(B7,3)="658"),"Signing",IF(OR(LEFT(B7,3)="666",LEFT(B7,3)="668",LEFT(B7,3)="672",LEFT(B7,3)="677",LEFT(B7,3)="678"),"Markings","Other"))))))))))))) -> Traffic control | E7: =IF(B7="","",'WS Import'!D17) -> MO | F7: =IF(B7="","",'WS Import'!E17) -> 7 | G7: 0 | H7: =IF(B7="","",IFERROR(INDEX('Unit Cost'!$N$6:$N$21,MATCH(B7,'Unit Cost'!$B$6:$B$21,0)),0)) -> 4300 | I7: =IF(B7="","",F7*IF(H7>0,H7,G7)) -> 30100 | J7: =IF(B7="","",IF(B7="500-7001",1,MarkupFactor)) -> 1.4163822 | K7: =IF(B7="","",IF(B7="500-7001",Mobilization!C11,IF(F7=0,0,IF(H7>0,H7,G7)*J7))) -> 6090.4437 | M7: =IF(B7="","",IF(L7="",K7,L7)) -> 6090.4437 | N7: =IF(B7="","",F7*M7) -> 42633.106 | O7: =IF(OR(B7="",$N$156=""),"",N7/$N$156) -> 0.016579792 | P7: 1800 | Q7: 3900 | R7: 8000 | S7: =IF(OR(B7="",F7=""),"",IF(M7=0,"ZERO PRICE",IF(AND(M7>0,M7<=0.05,Q7>1),"TOKEN PRICE",IF(AND(Q7>0,M7<P7*0.5),"UNDER BAND",IF(AND(R7>0,M7>R7*1.5),"OVER BAND",IF(AND(B7="500-7001",$N$156>0,N7/$N$156>0.1),"MOB > 10%","OK")))))) -> OK
A8: =IF('WS Import'!H18="","",ROW()-5) -> 3 | B8: =IF('WS Import'!H18="","",'WS Import'!H18) -> 503-7001 | C8: =IF('WS Import'!H18="","",'WS Import'!C18) -> Portable changeable message sign | D8: =IF(B8="","",IF('WS Import'!F18<>"",'WS Import'!F18,IF(LEFT(B8,3)="500","Mobilization",IF(OR(LEFT(B8,3)="502",LEFT(B8,3)="503",LEFT(B8,3)="505",LEFT(B8,3)="512"),"Traffic control",IF(LEFT(B8,3)="506","SW3P",IF(OR(LEFT(B8,3)="100",LEFT(B8,3)="104",LEFT(B8,3)="105",LEFT(B8,3)="110",LEFT(B8,3)="132"),"Earthwork",IF(LEFT(B8,3)="247","Base",IF(OR(LEFT(B8,3)="310",LEFT(B8,3)="316",LEFT(B8,3)="340",LEFT(B8,3)="341",LEFT(B8,3)="344",LEFT(B8,3)="354",LEFT(B8,4)="3076",LEFT(B8,4)="3077",LEFT(B8,4)="3080"),"Paving",IF(OR(LEFT(B8,3)="400",LEFT(B8,3)="416",LEFT(B8,3)="420",LEFT(B8,3)="422",LEFT(B8,3)="432",LEFT(B8,3)="450",LEFT(B8,3)="462",LEFT(B8,3)="464",LEFT(B8,3)="465",LEFT(B8,3)="466",LEFT(B8,3)="467",LEFT(B8,3)="496"),"Drainage",IF(OR(LEFT(B8,3)="164",LEFT(B8,3)="168",LEFT(B8,3)="169",LEFT(B8,3)="529",LEFT(B8,3)="530",LEFT(B8,3)="531"),"Roadside",IF(OR(LEFT(B8,3)="540",LEFT(B8,3)="542",LEFT(B8,3)="544",LEFT(B8,3)="545"),"Safety",IF(OR(LEFT(B8,3)="644",LEFT(B8,3)="636",LEFT(B8,3)="658"),"Signing",IF(OR(LEFT(B8,3)="666",LEFT(B8,3)="668",LEFT(B8,3)="672",LEFT(B8,3)="677",LEFT(B8,3)="678"),"Markings","Other"))))))))))))) -> Traffic control | E8: =IF(B8="","",'WS Import'!D18) -> DAY | F8: =IF(B8="","",'WS Import'!E18) -> 140 | G8: 55 | H8: =IF(B8="","",IFERROR(INDEX('Unit Cost'!$N$6:$N$21,MATCH(B8,'Unit Cost'!$B$6:$B$21,0)),0)) -> 0 | I8: =IF(B8="","",F8*IF(H8>0,H8,G8)) -> 7700 | J8: =IF(B8="","",IF(B8="500-7001",1,MarkupFactor)) -> 1.4163822 | K8: =IF(B8="","",IF(B8="500-7001",Mobilization!C11,IF(F8=0,0,IF(H8>0,H8,G8)*J8))) -> 77.901024 | M8: =IF(B8="","",IF(L8="",K8,L8)) -> 77.901024 | N8: =IF(B8="","",F8*M8) -> 10906.143 | O8: =IF(OR(B8="",$N$156=""),"",N8/$N$156) -> 0.0042413421 | P8: 40 | Q8: 90 | R8: 145 | S8: =IF(OR(B8="",F8=""),"",IF(M8=0,"ZERO PRICE",IF(AND(M8>0,M8<=0.05,Q8>1),"TOKEN PRICE",IF(AND(Q8>0,M8<P8*0.5),"UNDER BAND",IF(AND(R8>0,M8>R8*1.5),"OVER BAND",IF(AND(B8="500-7001",$N$156>0,N8/$N$156>0.1),"MOB > 10%","OK")))))) -> OK
A9: =IF('WS Import'!H19="","",ROW()-5) -> 4 | B9: =IF('WS Import'!H19="","",'WS Import'!H19) -> 505-7001 | C9: =IF('WS Import'!H19="","",'WS Import'!C19) -> TMA (stationary) | D9: =IF(B9="","",IF('WS Import'!F19<>"",'WS Import'!F19,IF(LEFT(B9,3)="500","Mobilization",IF(OR(LEFT(B9,3)="502",LEFT(B9,3)="503",LEFT(B9,3)="505",LEFT(B9,3)="512"),"Traffic control",IF(LEFT(B9,3)="506","SW3P",IF(OR(LEFT(B9,3)="100",LEFT(B9,3)="104",LEFT(B9,3)="105",LEFT(B9,3)="110",LEFT(B9,3)="132"),"Earthwork",IF(LEFT(B9,3)="247","Base",IF(OR(LEFT(B9,3)="310",LEFT(B9,3)="316",LEFT(B9,3)="340",LEFT(B9,3)="341",LEFT(B9,3)="344",LEFT(B9,3)="354",LEFT(B9,4)="3076",LEFT(B9,4)="3077",LEFT(B9,4)="3080"),"Paving",IF(OR(LEFT(B9,3)="400",LEFT(B9,3)="416",LEFT(B9,3)="420",LEFT(B9,3)="422",LEFT(B9,3)="432",LEFT(B9,3)="450",LEFT(B9,3)="462",LEFT(B9,3)="464",LEFT(B9,3)="465",LEFT(B9,3)="466",LEFT(B9,3)="467",LEFT(B9,3)="496"),"Drainage",IF(OR(LEFT(B9,3)="164",LEFT(B9,3)="168",LEFT(B9,3)="169",LEFT(B9,3)="529",LEFT(B9,3)="530",LEFT(B9,3)="531"),"Roadside",IF(OR(LEFT(B9,3)="540",LEFT(B9,3)="542",LEFT(B9,3)="544",LEFT(B9,3)="545"),"Safety",IF(OR(LEFT(B9,3)="644",LEFT(B9,3)="636",LEFT(B9,3)="658"),"Signing",IF(OR(LEFT(B9,3)="666",LEFT(B9,3)="668",LEFT(B9,3)="672",LEFT(B9,3)="677",LEFT(B9,3)="678"),"Markings","Other"))))))))))))) -> Traffic control | E9: =IF(B9="","",'WS Import'!D19) -> DAY | F9: =IF(B9="","",'WS Import'!E19) -> 140 | G9: 185 | H9: =IF(B9="","",IFERROR(INDEX('Unit Cost'!$N$6:$N$21,MATCH(B9,'Unit Cost'!$B$6:$B$21,0)),0)) -> 0 | I9: =IF(B9="","",F9*IF(H9>0,H9,G9)) -> 25900 | J9: =IF(B9="","",IF(B9="500-7001",1,MarkupFactor)) -> 1.4163822 | K9: =IF(B9="","",IF(B9="500-7001",Mobilization!C11,IF(F9=0,0,IF(H9>0,H9,G9)*J9))) -> 262.03072 | M9: =IF(B9="","",IF(L9="",K9,L9)) -> 262.03072 | N9: =IF(B9="","",F9*M9) -> 36684.3 | O9: =IF(OR(B9="",$N$156=""),"",N9/$N$156) -> 0.014266332 | P9: 50 | Q9: 150 | R9: 300 | S9: =IF(OR(B9="",F9=""),"",IF(M9=0,"ZERO PRICE",IF(AND(M9>0,M9<=0.05,Q9>1),"TOKEN PRICE",IF(AND(Q9>0,M9<P9*0.5),"UNDER BAND",IF(AND(R9>0,M9>R9*1.5),"OVER BAND",IF(AND(B9="500-7001",$N$156>0,N9/$N$156>0.1),"MOB > 10%","OK")))))) -> OK
A10: =IF('WS Import'!H20="","",ROW()-5) -> 5 | B10: =IF('WS Import'!H20="","",'WS Import'!H20) -> 505-7003 | C10: =IF('WS Import'!H20="","",'WS Import'!C20) -> TMA (mobile operation) | D10: =IF(B10="","",IF('WS Import'!F20<>"",'WS Import'!F20,IF(LEFT(B10,3)="500","Mobilization",IF(OR(LEFT(B10,3)="502",LEFT(B10,3)="503",LEFT(B10,3)="505",LEFT(B10,3)="512"),"Traffic control",IF(LEFT(B10,3)="506","SW3P",IF(OR(LEFT(B10,3)="100",LEFT(B10,3)="104",LEFT(B10,3)="105",LEFT(B10,3)="110",LEFT(B10,3)="132"),"Earthwork",IF(LEFT(B10,3)="247","Base",IF(OR(LEFT(B10,3)="310",LEFT(B10,3)="316",LEFT(B10,3)="340",LEFT(B10,3)="341",LEFT(B10,3)="344",LEFT(B10,3)="354",LEFT(B10,4)="3076",LEFT(B10,4)="3077",LEFT(B10,4)="3080"),"Paving",IF(OR(LEFT(B10,3)="400",LEFT(B10,3)="416",LEFT(B10,3)="420",LEFT(B10,3)="422",LEFT(B10,3)="432",LEFT(B10,3)="450",LEFT(B10,3)="462",LEFT(B10,3)="464",LEFT(B10,3)="465",LEFT(B10,3)="466",LEFT(B10,3)="467",LEFT(B10,3)="496"),"Drainage",IF(OR(LEFT(B10,3)="164",LEFT(B10,3)="168",LEFT(B10,3)="169",LEFT(B10,3)="529",LEFT(B10,3)="530",LEFT(B10,3)="531"),"Roadside",IF(OR(LEFT(B10,3)="540",LEFT(B10,3)="542",LEFT(B10,3)="544",LEFT(B10,3)="545"),"Safety",IF(OR(LEFT(B10,3)="644",LEFT(B10,3)="636",LEFT(B10,3)="658"),"Signing",IF(OR(LEFT(B10,3)="666",LEFT(B10,3)="668",LEFT(B10,3)="672",LEFT(B10,3)="677",LEFT(B10,3)="678"),"Markings","Other"))))))))))))) -> Traffic control | E10: =IF(B10="","",'WS Import'!D20) -> DAY | F10: =IF(B10="","",'WS Import'!E20) -> 30 | G10: 220 | H10: =IF(B10="","",IFERROR(INDEX('Unit Cost'!$N$6:$N$21,MATCH(B10,'Unit Cost'!$B$6:$B$21,0)),0)) -> 0 | I10: =IF(B10="","",F10*IF(H10>0,H10,G10)) -> 6600 | J10: =IF(B10="","",IF(B10="500-7001",1,MarkupFactor)) -> 1.4163822 | K10: =IF(B10="","",IF(B10="500-7001",Mobilization!C11,IF(F10=0,0,IF(H10>0,H10,G10)*J10))) -> 311.60409 | M10: =IF(B10="","",IF(L10="",K10,L10)) -> 311.60409 | N10: =IF(B10="","",F10*M10) -> 9348.1228 | O10: =IF(OR(B10="",$N$156=""),"",N10/$N$156) -> 0.0036354361 | P10: 40 | Q10: 110 | R10: 450 | S10: =IF(OR(B10="",F10=""),"",IF(M10=0,"ZERO PRICE",IF(AND(M10>0,M10<=0.05,Q10>1),"TOKEN PRICE",IF(AND(Q10>0,M10<P10*0.5),"UNDER BAND",IF(AND(R10>0,M10>R10*1.5),"OVER BAND",IF(AND(B10="500-7001",$N$156>0,N10/$N$156>0.1),"MOB > 10%","OK")))))) -> OK
A11: =IF('WS Import'!H21="","",ROW()-5) -> 6 | B11: =IF('WS Import'!H21="","",'WS Import'!H21) -> 506-7039 | C11: =IF('WS Import'!H21="","",'WS Import'!C21) -> Temp sedmt cont fence (install) | D11: =IF(B11="","",IF('WS Import'!F21<>"",'WS Import'!F21,IF(LEFT(B11,3)="500","Mobilization",IF(OR(LEFT(B11,3)="502",LEFT(B11,3)="503",LEFT(B11,3)="505",LEFT(B11,3)="512"),"Traffic control",IF(LEFT(B11,3)="506","SW3P",IF(OR(LEFT(B11,3)="100",LEFT(B11,3)="104",LEFT(B11,3)="105",LEFT(B11,3)="110",LEFT(B11,3)="132"),"Earthwork",IF(LEFT(B11,3)="247","Base",IF(OR(LEFT(B11,3)="310",LEFT(B11,3)="316",LEFT(B11,3)="340",LEFT(B11,3)="341",LEFT(B11,3)="344",LEFT(B11,3)="354",LEFT(B11,4)="3076",LEFT(B11,4)="3077",LEFT(B11,4)="3080"),"Paving",IF(OR(LEFT(B11,3)="400",LEFT(B11,3)="416",LEFT(B11,3)="420",LEFT(B11,3)="422",LEFT(B11,3)="432",LEFT(B11,3)="450",LEFT(B11,3)="462",LEFT(B11,3)="464",LEFT(B11,3)="465",LEFT(B11,3)="466",LEFT(B11,3)="467",LEFT(B11,3)="496"),"Drainage",IF(OR(LEFT(B11,3)="164",LEFT(B11,3)="168",LEFT(B11,3)="169",LEFT(B11,3)="529",LEFT(B11,3)="530",LEFT(B11,3)="531"),"Roadside",IF(OR(LEFT(B11,3)="540",LEFT(B11,3)="542",LEFT(B11,3)="544",LEFT(B11,3)="545"),"Safety",IF(OR(LEFT(B11,3)="644",LEFT(B11,3)="636",LEFT(B11,3)="658"),"Signing",IF(OR(LEFT(B11,3)="666",LEFT(B11,3)="668",LEFT(B11,3)="672",LEFT(B11,3)="677",LEFT(B11,3)="678"),"Markings","Other"))))))))))))) -> SW3P | E11: =IF(B11="","",'WS Import'!D21) -> LF | F11: =IF(B11="","",'WS Import'!E21) -> 4200 | G11: 0 | H11: =IF(B11="","",IFERROR(INDEX('Unit Cost'!$N$6:$N$21,MATCH(B11,'Unit Cost'!$B$6:$B$21,0)),0)) -> 2.1886667 | I11: =IF(B11="","",F11*IF(H11>0,H11,G11)) -> 9192.4 | J11: =IF(B11="","",IF(B11="500-7001",1,MarkupFactor)) -> 1.4163822 | K11: =IF(B11="","",IF(B11="500-7001",Mobilization!C11,IF(F11=0,0,IF(H11>0,H11,G11)*J11))) -> 3.0999886 | M11: =IF(B11="","",IF(L11="",K11,L11)) -> 3.0999886 | N11: =IF(B11="","",F11*M11) -> 13019.952 | O11: =IF(OR(B11="",$N$156=""),"",N11/$N$156) -> 0.0050633913 | P11: 3.25 | Q11: 4 | R11: 5.5 | S11: =IF(OR(B11="",F11=""),"",IF(M11=0,"ZERO PRICE",IF(AND(M11>0,M11<=0.05,Q11>1),"TOKEN PRICE",IF(AND(Q11>0,M11<P11*0.5),"UNDER BAND",IF(AND(R11>0,M11>R11*1.5),"OVER BAND",IF(AND(B11="500-7001",$N$156>0,N11/$N$156>0.1),"MOB > 10%","OK")))))) -> OK
A12: =IF('WS Import'!H22="","",ROW()-5) -> 7 | B12: =IF('WS Import'!H22="","",'WS Import'!H22) -> 506-7041 | C12: =IF('WS Import'!H22="","",'WS Import'!C22) -> Temp sedmt cont fence (remove) | D12: =IF(B12="","",IF('WS Import'!F22<>"",'WS Import'!F22,IF(LEFT(B12,3)="500","Mobilization",IF(OR(LEFT(B12,3)="502",LEFT(B12,3)="503",LEFT(B12,3)="505",LEFT(B12,3)="512"),"Traffic control",IF(LEFT(B12,3)="506","SW3P",IF(OR(LEFT(B12,3)="100",LEFT(B12,3)="104",LEFT(B12,3)="105",LEFT(B12,3)="110",LEFT(B12,3)="132"),"Earthwork",IF(LEFT(B12,3)="247","Base",IF(OR(LEFT(B12,3)="310",LEFT(B12,3)="316",LEFT(B12,3)="340",LEFT(B12,3)="341",LEFT(B12,3)="344",LEFT(B12,3)="354",LEFT(B12,4)="3076",LEFT(B12,4)="3077",LEFT(B12,4)="3080"),"Paving",IF(OR(LEFT(B12,3)="400",LEFT(B12,3)="416",LEFT(B12,3)="420",LEFT(B12,3)="422",LEFT(B12,3)="432",LEFT(B12,3)="450",LEFT(B12,3)="462",LEFT(B12,3)="464",LEFT(B12,3)="465",LEFT(B12,3)="466",LEFT(B12,3)="467",LEFT(B12,3)="496"),"Drainage",IF(OR(LEFT(B12,3)="164",LEFT(B12,3)="168",LEFT(B12,3)="169",LEFT(B12,3)="529",LEFT(B12,3)="530",LEFT(B12,3)="531"),"Roadside",IF(OR(LEFT(B12,3)="540",LEFT(B12,3)="542",LEFT(B12,3)="544",LEFT(B12,3)="545"),"Safety",IF(OR(LEFT(B12,3)="644",LEFT(B12,3)="636",LEFT(B12,3)="658"),"Signing",IF(OR(LEFT(B12,3)="666",LEFT(B12,3)="668",LEFT(B12,3)="672",LEFT(B12,3)="677",LEFT(B12,3)="678"),"Markings","Other"))))))))))))) -> SW3P | E12: =IF(B12="","",'WS Import'!D22) -> LF | F12: =IF(B12="","",'WS Import'!E22) -> 4200 | G12: 0.85 | H12: =IF(B12="","",IFERROR(INDEX('Unit Cost'!$N$6:$N$21,MATCH(B12,'Unit Cost'!$B$6:$B$21,0)),0)) -> 0 | I12: =IF(B12="","",F12*IF(H12>0,H12,G12)) -> 3570 | J12: =IF(B12="","",IF(B12="500-7001",1,MarkupFactor)) -> 1.4163822 | K12: =IF(B12="","",IF(B12="500-7001",Mobilization!C11,IF(F12=0,0,IF(H12>0,H12,G12)*J12))) -> 1.2039249 | M12: =IF(B12="","",IF(L12="",K12,L12)) -> 1.2039249 | N12: =IF(B12="","",F12*M12) -> 5056.4846 | O12: =IF(OR(B12="",$N$156=""),"",N12/$N$156) -> 0.0019664404 | P12: 0.75 | Q12: 1 | R12: 1.5 | S12: =IF(OR(B12="",F12=""),"",IF(M12=0,"ZERO PRICE",IF(AND(M12>0,M12<=0.05,Q12>1),"TOKEN PRICE",IF(AND(Q12>0,M12<P12*0.5),"UNDER BAND",IF(AND(R12>0,M12>R12*1.5),"OVER BAND",IF(AND(B12="500-7001",$N$156>0,N12/$N$156>0.1),"MOB > 10%","OK")))))) -> OK
A13: =IF('WS Import'!H23="","",ROW()-5) -> 8 | B13: =IF('WS Import'!H23="","",'WS Import'!H23) -> 100-7002 | C13: =IF('WS Import'!H23="","",'WS Import'!C23) -> Preparing right of way | D13: =IF(B13="","",IF('WS Import'!F23<>"",'WS Import'!F23,IF(LEFT(B13,3)="500","Mobilization",IF(OR(LEFT(B13,3)="502",LEFT(B13,3)="503",LEFT(B13,3)="505",LEFT(B13,3)="512"),"Traffic control",IF(LEFT(B13,3)="506","SW3P",IF(OR(LEFT(B13,3)="100",LEFT(B13,3)="104",LEFT(B13,3)="105",LEFT(B13,3)="110",LEFT(B13,3)="132"),"Earthwork",IF(LEFT(B13,3)="247","Base",IF(OR(LEFT(B13,3)="310",LEFT(B13,3)="316",LEFT(B13,3)="340",LEFT(B13,3)="341",LEFT(B13,3)="344",LEFT(B13,3)="354",LEFT(B13,4)="3076",LEFT(B13,4)="3077",LEFT(B13,4)="3080"),"Paving",IF(OR(LEFT(B13,3)="400",LEFT(B13,3)="416",LEFT(B13,3)="420",LEFT(B13,3)="422",LEFT(B13,3)="432",LEFT(B13,3)="450",LEFT(B13,3)="462",LEFT(B13,3)="464",LEFT(B13,3)="465",LEFT(B13,3)="466",LEFT(B13,3)="467",LEFT(B13,3)="496"),"Drainage",IF(OR(LEFT(B13,3)="164",LEFT(B13,3)="168",LEFT(B13,3)="169",LEFT(B13,3)="529",LEFT(B13,3)="530",LEFT(B13,3)="531"),"Roadside",IF(OR(LEFT(B13,3)="540",LEFT(B13,3)="542",LEFT(B13,3)="544",LEFT(B13,3)="545"),"Safety",IF(OR(LEFT(B13,3)="644",LEFT(B13,3)="636",LEFT(B13,3)="658"),"Signing",IF(OR(LEFT(B13,3)="666",LEFT(B13,3)="668",LEFT(B13,3)="672",LEFT(B13,3)="677",LEFT(B13,3)="678"),"Markings","Other"))))))))))))) -> Earthwork | E13: =IF(B13="","",'WS Import'!D23) -> STA | F13: =IF(B13="","",'WS Import'!E23) -> 18 | G13: 1400 | H13: =IF(B13="","",IFERROR(INDEX('Unit Cost'!$N$6:$N$21,MATCH(B13,'Unit Cost'!$B$6:$B$21,0)),0)) -> 0 | I13: =IF(B13="","",F13*IF(H13>0,H13,G13)) -> 25200 | J13: =IF(B13="","",IF(B13="500-7001",1,MarkupFactor)) -> 1.4163822 | K13: =IF(B13="","",IF(B13="500-7001",Mobilization!C11,IF(F13=0,0,IF(H13>0,H13,G13)*J13))) -> 1982.9351 | M13: =IF(B13="","",IF(L13="",K13,L13)) -> 1982.9351 | N13: =IF(B13="","",F13*M13) -> 35692.833 | O13: =IF(OR(B13="",$N$156=""),"",N13/$N$156) -> 0.013880756 | P13: 800 | Q13: 1500 | R13: 2800 | S13: =IF(OR(B13="",F13=""),"",IF(M13=0,"ZERO PRICE",IF(AND(M13>0,M13<=0.05,Q13>1),"TOKEN PRICE",IF(AND(Q13>0,M13<P13*0.5),"UNDER BAND",IF(AND(R13>0,M13>R13*1.5),"OVER BAND",IF(AND(B13="500-7001",$N$156>0,N13/$N$156>0.1),"MOB > 10%","OK")))))) -> OK
A14: =IF('WS Import'!H24="","",ROW()-5) -> 9 | B14: =IF('WS Import'!H24="","",'WS Import'!H24) -> 104-7006 | C14: =IF('WS Import'!H24="","",'WS Import'!C24) -> Removing conc (pav) | D14: =IF(B14="","",IF('WS Import'!F24<>"",'WS Import'!F24,IF(LEFT(B14,3)="500","Mobilization",IF(OR(LEFT(B14,3)="502",LEFT(B14,3)="503",LEFT(B14,3)="505",LEFT(B14,3)="512"),"Traffic control",IF(LEFT(B14,3)="506","SW3P",IF(OR(LEFT(B14,3)="100",LEFT(B14,3)="104",LEFT(B14,3)="105",LEFT(B14,3)="110",LEFT(B14,3)="132"),"Earthwork",IF(LEFT(B14,3)="247","Base",IF(OR(LEFT(B14,3)="310",LEFT(B14,3)="316",LEFT(B14,3)="340",LEFT(B14,3)="341",LEFT(B14,3)="344",LEFT(B14,3)="354",LEFT(B14,4)="3076",LEFT(B14,4)="3077",LEFT(B14,4)="3080"),"Paving",IF(OR(LEFT(B14,3)="400",LEFT(B14,3)="416",LEFT(B14,3)="420",LEFT(B14,3)="422",LEFT(B14,3)="432",LEFT(B14,3)="450",LEFT(B14,3)="462",LEFT(B14,3)="464",LEFT(B14,3)="465",LEFT(B14,3)="466",LEFT(B14,3)="467",LEFT(B14,3)="496"),"Drainage",IF(OR(LEFT(B14,3)="164",LEFT(B14,3)="168",LEFT(B14,3)="169",LEFT(B14,3)="529",LEFT(B14,3)="530",LEFT(B14,3)="531"),"Roadside",IF(OR(LEFT(B14,3)="540",LEFT(B14,3)="542",LEFT(B14,3)="544",LEFT(B14,3)="545"),"Safety",IF(OR(LEFT(B14,3)="644",LEFT(B14,3)="636",LEFT(B14,3)="658"),"Signing",IF(OR(LEFT(B14,3)="666",LEFT(B14,3)="668",LEFT(B14,3)="672",LEFT(B14,3)="677",LEFT(B14,3)="678"),"Markings","Other"))))))))))))) -> Earthwork | E14: =IF(B14="","",'WS Import'!D24) -> SY | F14: =IF(B14="","",'WS Import'!E24) -> 2800 | G14: 12.5 | H14: =IF(B14="","",IFERROR(INDEX('Unit Cost'!$N$6:$N$21,MATCH(B14,'Unit Cost'!$B$6:$B$21,0)),0)) -> 0 | I14: =IF(B14="","",F14*IF(H14>0,H14,G14)) -> 35000 | J14: =IF(B14="","",IF(B14="500-7001",1,MarkupFactor)) -> 1.4163822 | K14: =IF(B14="","",IF(B14="500-7001",Mobilization!C11,IF(F14=0,0,IF(H14>0,H14,G14)*J14))) -> 17.704778 | M14: =IF(B14="","",IF(L14="",K14,L14)) -> 17.704778 | N14: =IF(B14="","",F14*M14) -> 49573.379 | O14: =IF(OR(B14="",$N$156=""),"",N14/$N$156) -> 0.019278828 | P14: 8 | Q14: 14 | R14: 22 | S14: =IF(OR(B14="",F14=""),"",IF(M14=0,"ZERO PRICE",IF(AND(M14>0,M14<=0.05,Q14>1),"TOKEN PRICE",IF(AND(Q14>0,M14<P14*0.5),"UNDER BAND",IF(AND(R14>0,M14>R14*1.5),"OVER BAND",IF(AND(B14="500-7001",$N$156>0,N14/$N$156>0.1),"MOB > 10%","OK")))))) -> OK
A15: =IF('WS Import'!H25="","",ROW()-5) -> 10 | B15: =IF('WS Import'!H25="","",'WS Import'!H25) -> 110-7001 | C15: =IF('WS Import'!H25="","",'WS Import'!C25) -> Excavation (roadway) | D15: =IF(B15="","",IF('WS Import'!F25<>"",'WS Import'!F25,IF(LEFT(B15,3)="500","Mobilization",IF(OR(LEFT(B15,3)="502",LEFT(B15,3)="503",LEFT(B15,3)="505",LEFT(B15,3)="512"),"Traffic control",IF(LEFT(B15,3)="506","SW3P",IF(OR(LEFT(B15,3)="100",LEFT(B15,3)="104",LEFT(B15,3)="105",LEFT(B15,3)="110",LEFT(B15,3)="132"),"Earthwork",IF(LEFT(B15,3)="247","Base",IF(OR(LEFT(B15,3)="310",LEFT(B15,3)="316",LEFT(B15,3)="340",LEFT(B15,3)="341",LEFT(B15,3)="344",LEFT(B15,3)="354",LEFT(B15,4)="3076",LEFT(B15,4)="3077",LEFT(B15,4)="3080"),"Paving",IF(OR(LEFT(B15,3)="400",LEFT(B15,3)="416",LEFT(B15,3)="420",LEFT(B15,3)="422",LEFT(B15,3)="432",LEFT(B15,3)="450",LEFT(B15,3)="462",LEFT(B15,3)="464",LEFT(B15,3)="465",LEFT(B15,3)="466",LEFT(B15,3)="467",LEFT(B15,3)="496"),"Drainage",IF(OR(LEFT(B15,3)="164",LEFT(B15,3)="168",LEFT(B15,3)="169",LEFT(B15,3)="529",LEFT(B15,3)="530",LEFT(B15,3)="531"),"Roadside",IF(OR(LEFT(B15,3)="540",LEFT(B15,3)="542",LEFT(B15,3)="544",LEFT(B15,3)="545"),"Safety",IF(OR(LEFT(B15,3)="644",LEFT(B15,3)="636",LEFT(B15,3)="658"),"Signing",IF(OR(LEFT(B15,3)="666",LEFT(B15,3)="668",LEFT(B15,3)="672",LEFT(B15,3)="677",LEFT(B15,3)="678"),"Markings","Other"))))))))))))) -> Earthwork | E15: =IF(B15="","",'WS Import'!D25) -> CY | F15: =IF(B15="","",'WS Import'!E25) -> 8600 | G15: 0 | H15: =IF(B15="","",IFERROR(INDEX('Unit Cost'!$N$6:$N$21,MATCH(B15,'Unit Cost'!$B$6:$B$21,0)),0)) -> 6.1111111 | I15: =IF(B15="","",F15*IF(H15>0,H15,G15)) -> 52555.556 | J15: =IF(B15="","",IF(B15="500-7001",1,MarkupFactor)) -> 1.4163822 | K15: =IF(B15="","",IF(B15="500-7001",Mobilization!C11,IF(F15=0,0,IF(H15>0,H15,G15)*J15))) -> 8.6556693 | M15: =IF(B15="","",IF(L15="",K15,L15)) -> 8.6556693 | N15: =IF(B15="","",F15*M15) -> 74438.756 | O15: =IF(OR(B15="",$N$156=""),"",N15/$N$156) -> 0.028948843 | P15: 8 | Q15: 12 | R15: 18 | S15: =IF(OR(B15="",F15=""),"",IF(M15=0,"ZERO PRICE",IF(AND(M15>0,M15<=0.05,Q15>1),"TOKEN PRICE",IF(AND(Q15>0,M15<P15*0.5),"UNDER BAND",IF(AND(R15>0,M15>R15*1.5),"OVER BAND",IF(AND(B15="500-7001",$N$156>0,N15/$N$156>0.1),"MOB > 10%","OK")))))) -> OK
A16: =IF('WS Import'!H26="","",ROW()-5) -> 11 | B16: =IF('WS Import'!H26="","",'WS Import'!H26) -> 132-7005 | C16: =IF('WS Import'!H26="","",'WS Import'!C26) -> Embankment (final)(ord comp)(ty C) | D16: =IF(B16="","",IF('WS Import'!F26<>"",'WS Import'!F26,IF(LEFT(B16,3)="500","Mobilization",IF(OR(LEFT(B16,3)="502",LEFT(B16,3)="503",LEFT(B16,3)="505",LEFT(B16,3)="512"),"Traffic control",IF(LEFT(B16,3)="506","SW3P",IF(OR(LEFT(B16,3)="100",LEFT(B16,3)="104",LEFT(B16,3)="105",LEFT(B16,3)="110",LEFT(B16,3)="132"),"Earthwork",IF(LEFT(B16,3)="247","Base",IF(OR(LEFT(B16,3)="310",LEFT(B16,3)="316",LEFT(B16,3)="340",LEFT(B16,3)="341",LEFT(B16,3)="344",LEFT(B16,3)="354",LEFT(B16,4)="3076",LEFT(B16,4)="3077",LEFT(B16,4)="3080"),"Paving",IF(OR(LEFT(B16,3)="400",LEFT(B16,3)="416",LEFT(B16,3)="420",LEFT(B16,3)="422",LEFT(B16,3)="432",LEFT(B16,3)="450",LEFT(B16,3)="462",LEFT(B16,3)="464",LEFT(B16,3)="465",LEFT(B16,3)="466",LEFT(B16,3)="467",LEFT(B16,3)="496"),"Drainage",IF(OR(LEFT(B16,3)="164",LEFT(B16,3)="168",LEFT(B16,3)="169",LEFT(B16,3)="529",LEFT(B16,3)="530",LEFT(B16,3)="531"),"Roadside",IF(OR(LEFT(B16,3)="540",LEFT(B16,3)="542",LEFT(B16,3)="544",LEFT(B16,3)="545"),"Safety",IF(OR(LEFT(B16,3)="644",LEFT(B16,3)="636",LEFT(B16,3)="658"),"Signing",IF(OR(LEFT(B16,3)="666",LEFT(B16,3)="668",LEFT(B16,3)="672",LEFT(B16,3)="677",LEFT(B16,3)="678"),"Markings","Other"))))))))))))) -> Earthwork | E16: =IF(B16="","",'WS Import'!D26) -> CY | F16: =IF(B16="","",'WS Import'!E26) -> 4100 | G16: 0 | H16: =IF(B16="","",IFERROR(INDEX('Unit Cost'!$N$6:$N$21,MATCH(B16,'Unit Cost'!$B$6:$B$21,0)),0)) -> 13.686667 | I16: =IF(B16="","",F16*IF(H16>0,H16,G16)) -> 56115.333 | J16: =IF(B16="","",IF(B16="500-7001",1,MarkupFactor)) -> 1.4163822 | K16: =IF(B16="","",IF(B16="500-7001",Mobilization!C11,IF(F16=0,0,IF(H16>0,H16,G16)*J16))) -> 19.385552 | M16: =IF(B16="","",IF(L16="",K16,L16)) -> 19.385552 | N16: =IF(B16="","",F16*M16) -> 79480.762 | O16: =IF(OR(B16="",$N$156=""),"",N16/$N$156) -> 0.030909653 | P16: 8 | Q16: 14 | R16: 22 | S16: =IF(OR(B16="",F16=""),"",IF(M16=0,"ZERO PRICE",IF(AND(M16>0,M16<=0.05,Q16>1),"TOKEN PRICE",IF(AND(Q16>0,M16<P16*0.5),"UNDER BAND",IF(AND(R16>0,M16>R16*1.5),"OVER BAND",IF(AND(B16="500-7001",$N$156>0,N16/$N$156>0.1),"MOB > 10%","OK")))))) -> OK
